<?xml version="1.0" ?>
<!-- ======================================================================= -->
<!-- | This document was autogenerated by xacro from lbr_iiwa.urdf.xacro   | -->
<!-- | Original xacro: https://github.com/rtkg/lbr_iiwa/archive/master.zip | -->
<!-- | EDITING THIS FILE BY HAND IS NOT RECOMMENDED                        | -->
<!-- | Changes (kohlhoff):                                                 | -->
<!-- |   * Removed gazebo tags.                                            | -->
<!-- |   * Removed unused materials.                                       | -->
<!-- |   * Made mesh paths relative.                                       | -->
<!-- |   * Removed material fields from collision segments.                | -->
<!-- |   * Removed the self_collision_checking segment.                    | -->
<!-- |   * Removed transmission segments, since they didn't match the      | -->
<!-- |     convention, will have to added back later.                      | -->
<!-- ======================================================================= -->
<!--LICENSE:                                                                 -->
<!--Copyright (c) 2015, Robert Krug & Todor Stoyanov, AASS Research Center,  -->
<!--Orebro University, Sweden                                                -->
<!--All rights reserved.                                                     -->
<!--                                                                         -->
<!--Redistribution and use in source and binary forms, with or without       -->
<!--modification, are permitted provided that the following conditions are   -->
<!--met:                                                                     -->
<!--                                                                         -->
<!--1. Redistributions of source code must retain the above copyright notice,-->
<!--   this list of conditions and the following disclaimer.                 -->
<!--                                                                         -->
<!--2. Redistributions in binary form must reproduce the above copyright     -->
<!--   notice, this list of conditions and the following disclaimer in the   -->
<!--   documentation and/or other materials provided with the distribution.  -->
<!--                                                                         -->
<!--THIS SOFTWARE IS PROVIDED BY THE COPYRIGHT HOLDERS AND CONTRIBUTORS "AS  -->
<!--IS" AND ANY EXPRESS OR IMPLIED WARRANTIES, INCLUDING, BUT NOT LIMITED TO,-->
<!--THE IMPLIED WARRANTIES OF MERCHANTABILITY AND FITNESS FOR A PARTICULAR   -->
<!--PURPOSE ARE DISCLAIMED. IN NO EVENT SHALL THE COPYRIGHT HOLDER OR        -->
<!--CONTRIBUTORS BE LIABLE FOR ANY DIRECT, INDIRECT, INCIDENTAL, SPECIAL,    -->
<!--EXEMPLARY, OR CONSEQUENTIAL DAMAGES (INCLUDING, BUT NOT LIMITED TO,      -->
<!--PROCUREMENT OF SUBSTITUTE GOODS OR SERVICES; LOSS OF USE, DATA, OR       -->
<!--PROFITS; OR BUSINESS INTERRUPTION) HOWEVER CAUSED AND ON ANY THEORY OF   -->
<!--LIABILITY, WHETHER IN CONTRACT, STRICT LIABILITY, OR TORT (INCLUDING     -->
<!--NEGLIGENCE OR OTHERWISE) ARISING IN ANY WAY OUT OF THE USE OF THIS       -->
<!--SOFTWARE, EVEN IF ADVISED OF THE POSSIBILITY OF SUCH DAMAGE.             -->
<robot name="lbr_iiwa" xmlns:xacro="http://www.ros.org/wiki/xacro">
  <!-- Import Rviz colors -->
  <material name="Blue">
  <color rgba="0.5 0.7 1.0 1.0"/>      
</material>
  <material name="Black">
    <color rgba="0.0 0.0 0.0 1.0"/>
  </material>
  <material name="Green">
    <color rgba="0.0 0.8 0.0 1.0"/>
  </material>
  <material name="Grey">
    <color rgba="0.4 0.4 0.4 1.0"/>
  </material>
  <material name="Orange">
    <color rgba="1.0 0.4235294117647059 0.0392156862745098 1.0"/>
  </material>
  <material name="Brown">
    <color rgba="0.8705882352941177 0.8117647058823529 0.7647058823529411 1.0"/>
  </material>
  <material name="Red">
    <color rgba="0.8 0.0 0.0 1.0"/>
  </material>
  <material name="White">
    <color rgba="1.0 1.0 1.0 1.0"/>
  </material>
  <material name="LightGrey">
    <color rgba="0.7 0.7 0.7 1"/>
  </material>
  <material name="DarkGray">
    <color rgba="0.2 0.2 0.2 1"/>
  </material>
  <material name="DarkDarkGray">
    <color rgba="0.1 0.1 0.1 1"/>
  </material>


  <!--Import the lbr iiwa macro -->
  <!--Import Transmissions -->
  <!--Include Utilities -->
  <!--The following macros are adapted from the LWR 4 definitions of the RCPRG - https://github.com/RCPRG-ros-pkg/lwr_robot -->
  <!--Little helper macros to define the inertia matrix needed for links.-->
  <!--Cuboid-->
  <!--Cylinder: length is along the y-axis! -->
  <!--lbr-->
  <link name="lbr_iiwa_link_0">
    <inertial>
      <origin rpy="0 0 0" xyz="-0.1 0 0.07"/>
      <!--Increase mass from 5 Kg original to provide a stable base to carry the
          arm.-->
      <mass value="0.0"/>
      <inertia ixx="0.05" ixy="0" ixz="0" iyy="0.06" iyz="0" izz="0.03"/>
    </inertial>
    <visual>
      <origin rpy="0 0 0" xyz="0 0 0"/>
      <geometry>
        <mesh filename="meshes/kuka_iiwa/meshes/link_0.obj"/>
      </geometry>
      <material name="Grey"/>
    </visual>
    <collision>
      <origin rpy="0 0 0" xyz="0 0 0"/>
      <geometry>
        <mesh filename="meshes/kuka_iiwa/meshes/link_0.stl"/>
      </geometry>
    </collision>
  </link>
  <!-- joint between link_0 and link_1 -->
  <joint name="lbr_iiwa_joint_1" type="revolute">
    <parent link="lbr_iiwa_link_0"/>
    <child link="lbr_iiwa_link_1"/>
    <origin rpy="0 0 0" xyz="0 0 0.1575"/>
    <axis xyz="0 0 1"/>
    <limit effort="300" lower="-2.96705972839" upper="2.96705972839" velocity="10"/>
    <dynamics damping="0.5"/>
  </joint>
  <link name="lbr_iiwa_link_1">
    <inertial>
      <origin rpy="0 0 0" xyz="0 -0.03 0.12"/>
      <mass value="4"/>
      <inertia ixx="0.1" ixy="0" ixz="0" iyy="0.09" iyz="0" izz="0.02"/>
    </inertial>
    <visual>
      <origin rpy="0 0 0" xyz="0 0 0"/>
      <geometry>
        <mesh filename="meshes/kuka_iiwa/meshes/link_1.obj"/>
      </geometry>
      <material name="Blue"/>
    </visual>
    <collision>
      <origin rpy="0 0 0" xyz="0 0 0"/>
      <geometry>
        <mesh filename="meshes/kuka_iiwa/meshes/link_1.stl"/>
      </geometry>
    </collision>
  </link>
  <!-- joint between link_1 and link_2 -->
  <joint name="lbr_iiwa_joint_2" type="revolute">
    <parent link="lbr_iiwa_link_1"/>
    <child link="lbr_iiwa_link_2"/>
    <origin rpy="1.57079632679   0 3.14159265359" xyz="0 0 0.2025"/>
    <axis xyz="0 0 1"/>
    <limit effort="300" lower="-2.09439510239" upper="2.09439510239" velocity="10"/>
    <dynamics damping="0.5"/>
  </joint>
  <link name="lbr_iiwa_link_2">
    <inertial>
      <origin rpy="0 0 0" xyz="0.0003 0.059 0.042"/>
      <mass value="4"/>
      <inertia ixx="0.05" ixy="0" ixz="0" iyy="0.018" iyz="0" izz="0.044"/>
    </inertial>
    <visual>
      <origin rpy="0 0 0" xyz="0 0 0"/>
      <geometry>
        <mesh filename="meshes/kuka_iiwa/meshes/link_2.obj"/>
      </geometry>
      <material name="Blue"/>
    </visual>
    <collision>
      <origin rpy="0 0 0" xyz="0 0 0"/>
      <geometry>
        <mesh filename="meshes/kuka_iiwa/meshes/link_2.stl"/>
      </geometry>
    </collision>
  </link>
  <!-- joint between link_2 and link_3 -->
  <joint name="lbr_iiwa_joint_3" type="revolute">
    <parent link="lbr_iiwa_link_2"/>
    <child link="lbr_iiwa_link_3"/>
    <origin rpy="1.57079632679 0 3.14159265359" xyz="0 0.2045 0"/>
    <axis xyz="0 0 1"/>
    <limit effort="300" lower="-2.96705972839" upper="2.96705972839" velocity="10"/>
    <dynamics damping="0.5"/>
  </joint>
  <link name="lbr_iiwa_link_3">
    <inertial>
      <origin rpy="0 0 0" xyz="0 0.03 0.13"/>
      <mass value="3"/>
      <inertia ixx="0.08" ixy="0" ixz="0" iyy="0.075" iyz="0" izz="0.01"/>
    </inertial>
    <visual>
      <origin rpy="0 0 0" xyz="0 0 0"/>
      <geometry>
        <mesh filename="meshes/kuka_iiwa/meshes/link_3.obj"/>
      </geometry>
      <material name="Orange"/>
    </visual>
    <collision>
      <origin rpy="0 0 0" xyz="0 0 0"/>
      <geometry>
        <mesh filename="meshes/kuka_iiwa/meshes/link_3.stl"/>
      </geometry>
    </collision>
  </link>
  <!-- joint between link_3 and link_4 -->
  <joint name="lbr_iiwa_joint_4" type="revolute">
    <parent link="lbr_iiwa_link_3"/>
    <child link="lbr_iiwa_link_4"/>
    <origin rpy="1.57079632679 0 0" xyz="0 0 0.2155"/>
    <axis xyz="0 0 1"/>
    <limit effort="300" lower="-2.09439510239" upper="2.09439510239" velocity="10"/>
    <dynamics damping="0.5"/>
  </joint>
  <link name="lbr_iiwa_link_4">
    <inertial>
      <origin rpy="0 0 0" xyz="0 0.067 0.034"/>
      <mass value="2.7"/>
      <inertia ixx="0.03" ixy="0" ixz="0" iyy="0.01" iyz="0" izz="0.029"/>
    </inertial>
    <visual>
      <origin rpy="0 0 0" xyz="0 0 0"/>
      <geometry>
        <mesh filename="meshes/kuka_iiwa/meshes/link_4.obj"/>
      </geometry>
      <material name="Blue"/>
    </visual>
    <collision>
      <origin rpy="0 0 0" xyz="0 0 0"/>
      <geometry>
        <mesh filename="meshes/kuka_iiwa/meshes/link_4.stl"/>
      </geometry>
    </collision>
  </link>
  <!-- joint between link_4 and link_5 -->
  <joint name="lbr_iiwa_joint_5" type="revolute">
    <parent link="lbr_iiwa_link_4"/>
    <child link="lbr_iiwa_link_5"/>
    <origin rpy="-1.57079632679 3.14159265359 0" xyz="0 0.1845 0"/>
    <axis xyz="0 0 1"/>
    <limit effort="300" lower="-2.96705972839" upper="2.96705972839" velocity="10"/>
    <dynamics damping="0.5"/>
  </joint>
  <link name="lbr_iiwa_link_5">
    <inertial>
      <origin rpy="0 0 0" xyz="0.0001 0.021 0.076"/>
      <mass value="1.7"/>
      <inertia ixx="0.02" ixy="0" ixz="0" iyy="0.018" iyz="0" izz="0.005"/>
    </inertial>
    <visual>
      <origin rpy="0 0 0" xyz="0 0 0"/>
      <geometry>
        <mesh filename="meshes/kuka_iiwa/meshes/link_5.obj"/>
      </geometry>
      <material name="Blue"/>
    </visual>
    <collision>
      <origin rpy="0 0 0" xyz="0 0 0"/>
      <geometry>
        <mesh filename="meshes/kuka_iiwa/meshes/link_5.stl"/>
      </geometry>
    </collision>
  </link>
  <!-- joint between link_5 and link_6 -->
  <joint name="lbr_iiwa_joint_6" type="revolute">
    <parent link="lbr_iiwa_link_5"/>
    <child link="lbr_iiwa_link_6"/>
    <origin rpy="1.57079632679 0 0" xyz="0 0 0.2155"/>
    <axis xyz="0 0 1"/>
    <limit effort="300" lower="-2.09439510239" upper="2.09439510239" velocity="10"/>
    <dynamics damping="0.5"/>
  </joint>
  <link name="lbr_iiwa_link_6">
    <inertial>
      <origin rpy="0 0 0" xyz="0 0.0006 0.0004"/>
      <mass value="1.8"/>
      <inertia ixx="0.005" ixy="0" ixz="0" iyy="0.0036" iyz="0" izz="0.0047"/>
    </inertial>
    <visual>
      <origin rpy="0 0 0" xyz="0 0 0"/>
      <geometry>
        <mesh filename="meshes/kuka_iiwa/meshes/link_6.obj"/>
      </geometry>
      <material name="Orange"/>
    </visual>
    <collision>
      <origin rpy="0 0 0" xyz="0 0 0"/>
      <geometry>
        <mesh filename="meshes/kuka_iiwa/meshes/link_6.stl"/>
      </geometry>
    </collision>
  </link>
  <!-- joint between link_6 and link_7 -->
  <joint name="lbr_iiwa_joint_7" type="revolute">
    <parent link="lbr_iiwa_link_6"/>
    <child link="lbr_iiwa_link_7"/>
    <origin rpy="-1.57079632679 3.14159265359 0" xyz="0 0.081 0"/>
    <axis xyz="0 0 1"/>
    <limit effort="300" lower="-3.05432619099" upper="3.05432619099" velocity="10"/>
    <dynamics damping="0.5"/>
  </joint>
  <link name="lbr_iiwa_link_7">
    <inertial>
      <origin rpy="0 0 0" xyz="0 0 0.02"/>
      <mass value="0.3"/>
      <inertia ixx="0.001" ixy="0" ixz="0" iyy="0.001" iyz="0" izz="0.001"/>
    </inertial>
    <visual>
      <origin rpy="0 0 0" xyz="0 0 0"/>
      <geometry>
        <mesh filename="meshes/kuka_iiwa/meshes/link_7.obj"/>
      </geometry>
      <material name="Grey"/>
    </visual>
    <collision>
      <origin rpy="0 0 0" xyz="0 0 0"/>
      <geometry>
        <mesh filename="meshes/kuka_iiwa/meshes/link_7.stl"/>
      </geometry>
    </collision>
  </link>


  <!-- Make a base link. -->
  <joint name="gripper_connection" type="fixed">
    <origin rpy="0 0 0" xyz="0 0 0.042"/>
    <!-- <origin xyz="0 0 0" rpy="0 0 0"/> -->
    <parent link="lbr_iiwa_link_7"/>
    <child link="gripper_base"/>
  </joint>
  <link name="gripper_base" type="fixed">
    <inertial>
      <mass value="0"/>
      <inertia ixx="0" ixy="0" ixz="0" iyy="0" iyz="0" izz="0"/>
    </inertial>
  </link>

  <joint name="wsg50_plate_joint" type="fixed">
    <origin rpy="0 0 -1.5708" xyz="0 0 0"/>
    <!-- <origin xyz="0 0 0" rpy="0 0 -1.5708"/> -->
    <parent link="gripper_base"/>
    <child link="wsg50_plate"/>
  </joint>
  <!-- GRIPPER PLATE -->
  <link name="wsg50_plate">
    <inertial>
      <mass value="0.0"/>
      <!-- This is not the true mass -->
      <origin xyz="0 0 0"/>
      <inertia ixx="1.0" ixy="0.0" ixz="0.0" iyy="1.0" iyz="0.0" izz="1.0"/>
      <!-- This are not the true inertia -->
    </inertial>
    <visual>
      <origin rpy="0 0 0" xyz="0.0 0 0"/>
      <geometry>
        <mesh filename="package://meshes/wsg50/wsg50_plate.stl" scale="1 1 1"/>
        <!--box size="0.146 0.05 0.0735"/-->
      </geometry>
      <material name="grey">
        <color rgba="0.5 0.5 0.5 1"/>
      </material>
    </visual>
    <collision>
      <origin rpy="0 0 0" xyz="0.0 0 0"/>
      <geometry>
        <!--box size="0.146 0.05 0.0735"/-->
        <mesh filename="package://meshes/wsg50/wsg50_plate.stl" scale="1 1 1"/>
      </geometry>
    </collision>
  </link>
  <gazebo reference="wsg50_plate">
    <material>Gazebo/Grey</material>
    <turnGravityOff>false</turnGravityOff>
  </gazebo>
  <!-- GRIPPER -->
  <joint name="wsg50_anterior_gripper_joint" type="fixed">
    <origin rpy="0 0 0" xyz="0 0 0.01"/>
    <!-- <origin xyz="0 0 0" rpy="0 0 -1.5708"/> -->
    <parent link="wsg50_plate"/>
    <child link="wsg50_base_link"/>
  </joint>
  <!-- BASE LINK -->
  <link name="wsg50_base_link">
    <inertial>
      <mass value="1.48"/>
      <origin xyz="0.00363 -0.00829 0.015"/>
      <!--inertia ixx="1.0" ixy="0.0" ixz="0.0"
                    iyy="100.0" iyz="0.0"
                    izz="1.0" /-->
      <inertia ixx="0.0" ixy="0.0" ixz="0.0" iyy="0.0" iyz="0.0" izz="0.0"/>
    </inertial>
    <visual>
      <origin rpy="0 0 0" xyz="0.0 0 0"/>
      <geometry>
        <mesh filename="package://meshes/wsg50/WSG50_110.stl" scale="1 1 1"/>
        <!--box size="0.146 0.05 0.0735"/-->
      </geometry>
      <material name="grey">
        <color rgba="0.5 0.5 0.5 1"/>
      </material>
    </visual>
    <collision>
      <origin rpy="0 0 0" xyz="0.0 0 0"/>
      <geometry>
        <!--box size="0.146 0.05 0.0735"/-->
        <mesh filename="package://meshes/wsg50/WSG50_110.stl" scale="1 1 1"/>
      </geometry>
    </collision>
  </link>
  <gazebo reference="wsg50_base_link">
    <material>Gazebo/Grey</material>
    <turnGravityOff>false</turnGravityOff>
  </gazebo>
  <joint name="wsg50_center_joint" type="fixed">
    <origin rpy="0 0 0" xyz="0 0 0.023"/>
    <!--origin xyz="-0.0067 0 0.049" rpy="0 0 0" /-->
    <parent link="wsg50_base_link"/>
    <child link="wsg50_center"/>
  </joint>
  <link name="wsg50_center">
    <inertial>
      <mass value="0"/>
      <inertia ixx="0" ixy="0" ixz="0" iyy="0" iyz="0" izz="0"/>
    </inertial>
  </link>
  <!-- GRIPPER LEFT -->
  <joint name="wsg50_finger_left_joint" type="prismatic">
    <limit effort="1.0" lower="-0.055" upper="0.0" velocity="1.0"/>
    <origin rpy="0 0 0" xyz="0 0 0"/>
    <!--origin xyz="-0.0067 0 0.049" rpy="0 0 0" /-->
    <parent link="wsg50_base_link"/>
    <child link="wsg50_gripper_left"/>
    <dynamics damping="100" friction="100"/>
    <axis xyz="1 0 0"/>
  </joint>
  <transmission name="wsg50_base_trans_left">
    <type>transmission_interface/SimpleTransmission</type>
    <actuator name="wsg50_base_motor_left">
      <mechanicalReduction>1</mechanicalReduction>
    </actuator>
    <joint name="wsg50_finger_left_joint">
      <hardwareInterface>hardware_interface/PositionJointInterface</hardwareInterface>
    </joint>
  </transmission>
  <link name="wsg50_gripper_left">
    <inertial>
      <mass value="0.1"/>
      <origin xyz="0 0 0"/>
      <inertia ixx="1.0" ixy="0.0" ixz="0.0" iyy="1.0" iyz="0.0" izz="1.0"/>
    </inertial>
    <visual>
      <origin rpy="0 0 0" xyz="0.0 0 0"/>
      <geometry>
        <mesh filename="package://meshes/wsg50/GUIDE_WSG50_110.stl" scale="0.001 0.001 0.001"/>
        <!--box size="0.0175 0.03 0.024"/-->
      </geometry>
      <material name="black">
        <color rgba="0 0 0 1"/>
      </material>
    </visual>
    <collision>
      <origin rpy="0 0 0" xyz="0 0 0"/>
      <geometry>
        <!--box size="0.0175 0.03 0.024"/-->
        <mesh filename="package://meshes/wsg50/GUIDE_WSG50_110.stl" scale="0.001 0.001 0.001"/>
      </geometry>
    </collision>
    <contact_coefficients kd="1.0" kp="1000.0" mu="0"/>
  </link>
  <gazebo reference="wsg50_gripper_left">
    <material>Gazebo/Blue</material>
    <turnGravityOff>false</turnGravityOff>
  </gazebo>
  <!-- GRIPPER RIGHT -->
  <joint name="wsg50_finger_right_joint" type="prismatic">
    <limit effort="1.0" lower="0.0" upper="0.055" velocity="1.0"/>
    <origin rpy="0 0 3.14159" xyz="0 0 0"/>
    <parent link="wsg50_base_link"/>
    <child link="wsg50_gripper_right"/>
    <axis xyz="-1 0 0"/>
    <dynamics damping="100" friction="100"/>
  </joint>
  <transmission name="wsg50_base_trans_right">
    <type>transmission_interface/SimpleTransmission</type>
    <actuator name="wsg50_base_motor_right">
      <mechanicalReduction>1</mechanicalReduction>
    </actuator>
    <joint name="wsg50_finger_right_joint">
      <hardwareInterface>hardware_interface/PositionJointInterface</hardwareInterface>
    </joint>
  </transmission>
  <link name="wsg50_gripper_right">
    <inertial>
      <mass value="0.1"/>
      <origin xyz="0 0 0"/>
      <inertia ixx="1.0" ixy="0.0" ixz="0.0" iyy="1.0" iyz="0.0" izz="1.0"/>
    </inertial>
    <visual>
      <origin rpy="0 0 0" xyz="0.0 0 0"/>
      <geometry>
        <mesh filename="package://meshes/wsg50/GUIDE_WSG50_110.stl" scale="0.001 0.001 0.001"/>
        <!--box size="0.0175 0.03 0.024"/-->
      </geometry>
      <material name="black">
        <color rgba="0 0 0 1"/>
      </material>
    </visual>
    <collision>
      <origin rpy="0 0 0" xyz="0 0 0"/>
      <geometry>
        <!--box size="0.0175 0.03 0.024"/-->
        <mesh filename="package://meshes/wsg50/GUIDE_WSG50_110.stl" scale="0.001 0.001 0.001"/>
      </geometry>
    </collision>
    <contact_coefficients kd="1.0" kp="1000.0" mu="0"/>
  </link>
  <gazebo reference="gripper_right">
    <material>Gazebo/White</material>
    <turnGravityOff>false</turnGravityOff>
  </gazebo>
  <!--  ~~~~~~~~~~~~~~~~~~~~~~~~~~~~~~~~~~~~~~~~~~~~~~~~~~~~~~~~~~~~~~~~~~~~~~~~~~~~~~~~~~~~~~~      -->
  <!--  ~~~~~~~~ FINGERS ~~~~~~~~~~~~~~~~~~~~~~~~~~~~~~~~~~~~~~~~~~~~~~~~~~~~~~~~~~~~~~~~~~~~~~      -->
  <!--  ~~~~~~~~~~~~~~~~~~~~~~~~~~~~~~~~~~~~~~~~~~~~~~~~~~~~~~~~~~~~~~~~~~~~~~~~~~~~~~~~~~~~~~~      -->
  <!-- Flipped Bubbles -->
  <!-- LEFT FINGER -->
  <joint name="wsg50_guide_joint_finger_left" type="fixed">
    <origin rpy="0 0 0" xyz="-0.009 0 .089"/>
    <parent link="wsg50_gripper_left"/>
    <child link="wsg50_finger_left"/>
    <dynamics damping="100" friction="100"/>
    <axis xyz="1 0 0"/>
    <limit effort="100" velocity="100"/>
  </joint>
  <link name="wsg50_finger_left">
    <inertial>
      <mass value="0.1"/>
      <origin xyz="0 0 0"/>
      <inertia ixx="1.0" ixy="0.0" ixz="0.0" iyy="1.0" iyz="0.0" izz="1.0"/>
    </inertial>
    <visual>
      <origin rpy="0 -1.8661 0" xyz="-0.0252755 0 0.0434163"/>
      <geometry>
        <mesh filename="package://meshes/bubbles/collision/bubble_flipped_inflated.stl" scale="0.001 0.001 0.001"/>
      </geometry>
      <material name="pastel">
        <color rgba="0.8588 0.5255 0.6588 1"/>
      </material>
    </visual>
    <collision>
      <origin rpy="0 -1.8661 0" xyz="-0.0252755 0 0.0434163"/>
      <geometry>
        <mesh filename="package://meshes/bubbles/collision/bubble_flipped_inflated.stl" scale="0.001 0.001 0.001"/>
      </geometry>
    </collision>
    <contact_coefficients kd="1.0" kp="1000.0" mu="0"/>
  </link>
  <!-- LEFT CAMERA FRAME -->
  <joint name="wsg50_left_bubble_camera_frame_fake_joint" type="fixed">
    <origin rpy="0 -1.8661 0" xyz="-0.0252755 0 0.0434163"/>
    <parent link="wsg50_finger_left"/>
    <child link="left_bubble_camera_frame"/>
  </joint>
  <link name="left_bubble_camera_frame">
    <inertial>
      <mass value="0.0"/>
      <origin xyz="0 0 0"/>
      <inertia ixx="0.0" ixy="0.0" ixz="0.0" iyy="0.0" iyz="0.0" izz="0.0"/>
    </inertial>
  </link>
  <!-- RIGHT FINGER -->
  <joint name="wsg50_guide_joint_finger_right" type="fixed">
    <origin rpy="0 0 0" xyz="-0.009 0 .089"/>
    <parent link="wsg50_gripper_right"/>
    <child link="wsg50_finger_right"/>
    <dynamics damping="100" friction="100"/>
    <axis xyz="1 0 0"/>
    <limit effort="100" velocity="100"/>
  </joint>
  <link name="wsg50_finger_right">
    <inertial>
      <mass value="0.1"/>
      <origin xyz="0 0 0"/>
      <inertia ixx="1.0" ixy="0.0" ixz="0.0" iyy="1.0" iyz="0.0" izz="1.0"/>
    </inertial>
    <visual>
      <origin rpy="0 -1.8661 0" xyz="-0.0252755 0 0.0434163"/>
      <geometry>
        <mesh filename="package://meshes/bubbles/collision/bubble_flipped_inflated.stl" scale="0.001 0.001 0.001"/>
      </geometry>
      <material name="pastel">
        <color rgba="0.8588 0.5255 0.6588 1"/>
      </material>
    </visual>
    <collision>
      <origin rpy="0 -1.8661 0" xyz="-0.0252755 0 0.0434163"/>
      <geometry>
        <mesh filename="package://meshes/bubbles/visual/bubble_flipped_inflated.stl" scale="0.001 0.001 0.001"/>
      </geometry>
    </collision>
    <contact_coefficients kd="1.0" kp="1000.0" mu="0"/>
    <contact_coefficients kd="1.0" kp="1000.0" mu="0"/>
  </link>
  <!-- RIGHT CAMERA FRAME -->
  <joint name="wsg50_right_bubble_camera_frame_fake_joint" type="fixed">
    <origin rpy="0 -1.8661 0" xyz="-0.0252755 0 0.0434163"/>
    <parent link="wsg50_finger_right"/>
    <child link="right_bubble_camera_frame"/>
  </joint>
  <link name="right_bubble_camera_frame">
    <inertial>
      <mass value="0.0"/>
      <origin xyz="0 0 0"/>
      <inertia ixx="0.0" ixy="0.0" ixz="0.0" iyy="0.0" iyz="0.0" izz="0.0"/>
    </inertial>
  </link>
  <!--  ==================================  END OF FINGER SELECTION  ==================================  -->
  <gazebo reference="wsg50_finger_left">
    <material>Gazebo/Blue</material>
    <turnGravityOff>false</turnGravityOff>
  </gazebo>
  <gazebo reference="wsg50_finger_right">
    <material>Gazebo/White</material>
    <turnGravityOff>false</turnGravityOff>
  </gazebo>
  <!-- GRASP FRAME -->
  <joint name="wsg50_grasp_frame_fake_joint" type="fixed">
    <!-- <origin xyz="0 0 0" rpy="0 0 -1.5708"/> -->
    <parent link="wsg50_base_link"/>
    <child link="grasp_frame"/>
  </joint>
  <link name="grasp_frame">
    <inertial>
      <mass value="0.0"/>
      <origin xyz="0 0 0"/>
      <inertia ixx="0.0" ixy="0.0" ixz="0.0" iyy="0.0" iyz="0.0" izz="0.0"/>
    </inertial>
  </link>
  <!-- RIGHT FINGER TIP FRAME -->
  <joint name="wsg50_right_finger_tip_fake_joint" type="fixed">
    <origin rpy="0 0 3.14159" xyz="0 0 0.121"/>
    <!-- May be worth considering the parameter finger_tip-->
    <!-- <origin xyz="0 0 0" rpy="0 0 -1.5708"/> -->
    <parent link="wsg50_finger_right"/>
    <child link="wsg50_finger_right_tip"/>
  </joint>
  <link name="wsg50_finger_right_tip">
    <inertial>
      <mass value="0.0"/>
      <origin xyz="0 0 0"/>
      <inertia ixx="0.0" ixy="0.0" ixz="0.0" iyy="0.0" iyz="0.0" izz="0.0"/>
    </inertial>
  </link>
  <!-- LEFT FINGER TIP FRAME -->
  <joint name="wsg50_left_finger_tip_fake_joint" type="fixed">
    <origin rpy="0 0 0" xyz="0 0 0.121"/>
    <!-- May be worth considering the parameter finger_tip-->
    <!-- <origin xyz="0 0 0" rpy="0 0 -1.5708"/> -->
    <parent link="wsg50_finger_left"/>
    <child link="wsg50_finger_left_tip"/>
  </joint>
  <link name="wsg50_finger_left_tip">
    <inertial>
      <mass value="0.0"/>
      <origin xyz="0 0 0"/>
      <inertia ixx="0.0" ixy="0.0" ixz="0.0" iyy="0.0" iyz="0.0" izz="0.0"/>
    </inertial>
  </link>

</robot>

